<?xml version="1.0" ?>
<!-- =================================================================================== -->
<!-- |    This document was autogenerated by xacro from LeggedRobot                    | -->
<!-- |    EDITING THIS FILE BY HAND IS NOT RECOMMENDED                                 | -->
<!-- =================================================================================== -->
<robot xmlns:xacro="http://www.ros.org/wiki/xacro" name="LeggedRobot">
  <material name="silver">
    <color rgba="0.700 0.700 0.700 1.000"/>
  </material>
  <transmission name="Revolute 1_tran">
    <type>transmission_interface/SimpleTransmission</type>
    <joint name="Revolute 1">
      <hardwareInterface>hardware_interface/EffortJointInterface</hardwareInterface>
    </joint>
    <actuator name="Revolute 1_actr">
      <hardwareInterface>hardware_interface/EffortJointInterface</hardwareInterface>
      <mechanicalReduction>1</mechanicalReduction>
    </actuator>
  </transmission>
  <transmission name="Revolute 2_tran">
    <type>transmission_interface/SimpleTransmission</type>
    <joint name="Revolute 2">
      <hardwareInterface>hardware_interface/EffortJointInterface</hardwareInterface>
    </joint>
    <actuator name="Revolute 2_actr">
      <hardwareInterface>hardware_interface/EffortJointInterface</hardwareInterface>
      <mechanicalReduction>1</mechanicalReduction>
    </actuator>
  </transmission>
  <transmission name="Revolute 3_tran">
    <type>transmission_interface/SimpleTransmission</type>
    <joint name="Revolute 3">
      <hardwareInterface>hardware_interface/EffortJointInterface</hardwareInterface>
    </joint>
    <actuator name="Revolute 3_actr">
      <hardwareInterface>hardware_interface/EffortJointInterface</hardwareInterface>
      <mechanicalReduction>1</mechanicalReduction>
    </actuator>
  </transmission>
  <transmission name="Revolute 4_tran">
    <type>transmission_interface/SimpleTransmission</type>
    <joint name="Revolute 4">
      <hardwareInterface>hardware_interface/EffortJointInterface</hardwareInterface>
    </joint>
    <actuator name="Revolute 4_actr">
      <hardwareInterface>hardware_interface/EffortJointInterface</hardwareInterface>
      <mechanicalReduction>1</mechanicalReduction>
    </actuator>
  </transmission>
  <transmission name="Revolute 5_tran">
    <type>transmission_interface/SimpleTransmission</type>
    <joint name="Revolute 5">
      <hardwareInterface>hardware_interface/EffortJointInterface</hardwareInterface>
    </joint>
    <actuator name="Revolute 5_actr">
      <hardwareInterface>hardware_interface/EffortJointInterface</hardwareInterface>
      <mechanicalReduction>1</mechanicalReduction>
    </actuator>
  </transmission>
  <transmission name="Revolute 6_tran">
    <type>transmission_interface/SimpleTransmission</type>
    <joint name="Revolute 6">
      <hardwareInterface>hardware_interface/EffortJointInterface</hardwareInterface>
    </joint>
    <actuator name="Revolute 6_actr">
      <hardwareInterface>hardware_interface/EffortJointInterface</hardwareInterface>
      <mechanicalReduction>1</mechanicalReduction>
    </actuator>
  </transmission>
  <transmission name="Revolute 7_tran">
    <type>transmission_interface/SimpleTransmission</type>
    <joint name="Revolute 7">
      <hardwareInterface>hardware_interface/EffortJointInterface</hardwareInterface>
    </joint>
    <actuator name="Revolute 7_actr">
      <hardwareInterface>hardware_interface/EffortJointInterface</hardwareInterface>
      <mechanicalReduction>1</mechanicalReduction>
    </actuator>
  </transmission>
  <transmission name="Revolute 8_tran">
    <type>transmission_interface/SimpleTransmission</type>
    <joint name="Revolute 8">
      <hardwareInterface>hardware_interface/EffortJointInterface</hardwareInterface>
    </joint>
    <actuator name="Revolute 8_actr">
      <hardwareInterface>hardware_interface/EffortJointInterface</hardwareInterface>
      <mechanicalReduction>1</mechanicalReduction>
    </actuator>
  </transmission>
  <transmission name="Revolute 9_tran">
    <type>transmission_interface/SimpleTransmission</type>
    <joint name="Revolute 9">
      <hardwareInterface>hardware_interface/EffortJointInterface</hardwareInterface>
    </joint>
    <actuator name="Revolute 9_actr">
      <hardwareInterface>hardware_interface/EffortJointInterface</hardwareInterface>
      <mechanicalReduction>1</mechanicalReduction>
    </actuator>
  </transmission>
  <transmission name="Revolute 10_tran">
    <type>transmission_interface/SimpleTransmission</type>
    <joint name="Revolute 10">
      <hardwareInterface>hardware_interface/EffortJointInterface</hardwareInterface>
    </joint>
    <actuator name="Revolute 10_actr">
      <hardwareInterface>hardware_interface/EffortJointInterface</hardwareInterface>
      <mechanicalReduction>1</mechanicalReduction>
    </actuator>
  </transmission>
  <transmission name="Revolute 11_tran">
    <type>transmission_interface/SimpleTransmission</type>
    <joint name="Revolute 11">
      <hardwareInterface>hardware_interface/EffortJointInterface</hardwareInterface>
    </joint>
    <actuator name="Revolute 11_actr">
      <hardwareInterface>hardware_interface/EffortJointInterface</hardwareInterface>
      <mechanicalReduction>1</mechanicalReduction>
    </actuator>
  </transmission>
  <transmission name="Revolute 12_tran">
    <type>transmission_interface/SimpleTransmission</type>
    <joint name="Revolute 12">
      <hardwareInterface>hardware_interface/EffortJointInterface</hardwareInterface>
    </joint>
    <actuator name="Revolute 12_actr">
      <hardwareInterface>hardware_interface/EffortJointInterface</hardwareInterface>
      <mechanicalReduction>1</mechanicalReduction>
    </actuator>
  </transmission>
  <gazebo>
    <plugin name="control" filename="libgazebo_ros_control.so"/>
  </gazebo>
  <gazebo reference="base_link">
    <material>Gazebo/Silver</material>
    <mu1>0.2</mu1>
    <mu2>0.2</mu2>
    <selfCollide>true</selfCollide>
    <gravity>true</gravity>
  </gazebo>
  <gazebo reference="Hip_v1__1__1">
    <material>Gazebo/Silver</material>
    <mu1>0.2</mu1>
    <mu2>0.2</mu2>
    <selfCollide>true</selfCollide>
  </gazebo>
  <gazebo reference="Hip_v1_1">
    <material>Gazebo/Silver</material>
    <mu1>0.2</mu1>
    <mu2>0.2</mu2>
    <selfCollide>true</selfCollide>
  </gazebo>
  <gazebo reference="Hip_joint_v1_1">
    <material>Gazebo/Silver</material>
    <mu1>0.2</mu1>
    <mu2>0.2</mu2>
    <selfCollide>true</selfCollide>
  </gazebo>
  <gazebo reference="Ankle_v1_1">
    <material>Gazebo/Silver</material>
    <mu1>0.2</mu1>
    <mu2>0.2</mu2>
    <selfCollide>true</selfCollide>
  </gazebo>
  <gazebo reference="Upper_leg_v2__1__1">
    <material>Gazebo/Silver</material>
    <mu1>0.2</mu1>
    <mu2>0.2</mu2>
    <selfCollide>true</selfCollide>
  </gazebo>
  <gazebo reference="Upper_leg_v2_1">
    <material>Gazebo/Silver</material>
    <mu1>0.2</mu1>
    <mu2>0.2</mu2>
    <selfCollide>true</selfCollide>
  </gazebo>
  <gazebo reference="Lower_leg_v2__1__1">
    <material>Gazebo/Silver</material>
    <mu1>0.2</mu1>
    <mu2>0.2</mu2>
    <selfCollide>true</selfCollide>
  </gazebo>
  <gazebo reference="Lower_leg_v2_1">
    <material>Gazebo/Silver</material>
    <mu1>0.2</mu1>
    <mu2>0.2</mu2>
    <selfCollide>true</selfCollide>
  </gazebo>
  <gazebo reference="Ankle_v1__1__1">
    <material>Gazebo/Silver</material>
    <mu1>0.2</mu1>
    <mu2>0.2</mu2>
    <selfCollide>true</selfCollide>
  </gazebo>
  <gazebo reference="Ankle_v1__2__1">
    <material>Gazebo/Silver</material>
    <mu1>0.2</mu1>
    <mu2>0.2</mu2>
    <selfCollide>true</selfCollide>
  </gazebo>
  <gazebo reference="Foot_v1__1__1">
    <material>Gazebo/Silver</material>
    <mu1>0.2</mu1>
    <mu2>0.2</mu2>
    <selfCollide>true</selfCollide>
  </gazebo>
  <gazebo reference="Foot_v1_1">
    <material>Gazebo/Silver</material>
    <mu1>0.2</mu1>
    <mu2>0.2</mu2>
    <selfCollide>true</selfCollide>
  </gazebo>
  <link name="base_link">
    <inertial>
      <origin xyz="-2.7471154310606345e-17 -1.7035252624411454e-17 0.07519859671235585" rpy="0 0 0"/>
      <mass value="7.805254806134041"/>
      <inertia ixx="0.044074" iyy="0.026397" izz="0.041232" ixy="-0.0" iyz="0.0" ixz="-0.0"/>
    </inertial>
    <visual>
      <origin xyz="0 0 0" rpy="0 0 0"/>
      <geometry>
        <mesh filename="../meshes/base_link.stl"/>
      </geometry>
      <material name="silver"/>
    </visual>
    <collision>
      <origin xyz="0 0 0" rpy="0 0 0"/>
      <geometry>
        <mesh filename="../meshes/base_link.stl"/>
      </geometry>
    </collision>
  </link>
  <link name="Hip_v1__1__1">
    <inertial>
      <origin xyz="0.0022984441069888208 -5.53402129122027e-07 -0.013356564577291863" rpy="0 0 0"/>
      <mass value="0.07120981938348954"/>
      <inertia ixx="2.6e-05" iyy="7e-05" izz="5.4e-05" ixy="0.0" iyz="0.0" ixz="0.0"/>
    </inertial>
    <visual>
      <origin xyz="0.0 -0.073437 -0.0" rpy="0 0 0"/>
      <geometry>
        <mesh filename="../meshes/Hip_v1__1__1.stl"/>
      </geometry>
      <material name="silver"/>
    </visual>
    <collision>
      <origin xyz="0.0 -0.073437 -0.0" rpy="0 0 0"/>
      <geometry>
        <mesh filename="../meshes/Hip_v1__1__1.stl"/>
      </geometry>
    </collision>
  </link>
  <link name="Hip_v1_1">
    <inertial>
      <origin xyz="0.0022984441069888546 -1.1401027765201022e-06 -0.013356564577292111" rpy="0 0 0"/>
      <mass value="0.07120981938348954"/>
      <inertia ixx="2.6e-05" iyy="7e-05" izz="5.4e-05" ixy="0.0" iyz="0.0" ixz="0.0"/>
    </inertial>
    <visual>
      <origin xyz="0.0 0.073437 -0.0" rpy="0 0 0"/>
      <geometry>
        <mesh filename="../meshes/Hip_v1_1.stl"/>
      </geometry>
      <material name="silver"/>
    </visual>
    <collision>
      <origin xyz="0.0 0.073437 -0.0" rpy="0 0 0"/>
      <geometry>
        <mesh filename="../meshes/Hip_v1_1.stl"/>
      </geometry>
    </collision>
  </link>
  <link name="Hip_joint_v1_1">
    <inertial>
      <origin xyz="0.036777802683292456 8.700605495792768e-08 -2.3112192325543124e-05" rpy="0 0 0"/>
      <mass value="0.015566398617684687"/>
      <inertia ixx="1e-06" iyy="5e-06" izz="6e-06" ixy="-0.0" iyz="-0.0" ixz="-0.0"/>
    </inertial>
    <visual>
      <origin xyz="0.035 -0.073437 0.045328" rpy="0 0 0"/>
      <geometry>
        <mesh filename="../meshes/Hip_joint_v1_1.stl"/>
      </geometry>
      <material name="silver"/>
    </visual>
    <collision>
      <origin xyz="0.035 -0.073437 0.045328" rpy="0 0 0"/>
      <geometry>
        <mesh filename="../meshes/Hip_joint_v1_1.stl"/>
      </geometry>
    </collision>
  </link>
  <link name="Ankle_v1_1">
    <inertial>
      <origin xyz="0.03695837800314751 -5.16086539059657e-07 -1.8276981016612792e-05" rpy="0 0 0"/>
      <mass value="0.013454867594222361"/>
      <inertia ixx="0.0" iyy="5e-06" izz="5e-06" ixy="-0.0" iyz="-0.0" ixz="-0.0"/>
    </inertial>
    <visual>
      <origin xyz="0.035 0.073437 0.045328" rpy="0 0 0"/>
      <geometry>
        <mesh filename="../meshes/Ankle_v1_1.stl"/>
      </geometry>
      <material name="silver"/>
    </visual>
    <collision>
      <origin xyz="0.035 0.073437 0.045328" rpy="0 0 0"/>
      <geometry>
        <mesh filename="../meshes/Ankle_v1_1.stl"/>
      </geometry>
    </collision>
  </link>
  <link name="Upper_leg_v2__1__1">
    <inertial>
      <origin xyz="-6.801099966390877e-17 0.020000293350323717 -0.07192876729347258" rpy="0 0 0"/>
      <mass value="0.1431308285816426"/>
      <inertia ixx="0.000346" iyy="0.000326" izz="5.6e-05" ixy="0.0" iyz="0.0" ixz="0.0"/>
    </inertial>
    <visual>
      <origin xyz="0.0 -0.053437 0.045399" rpy="0 0 0"/>
      <geometry>
        <mesh filename="../meshes/Upper_leg_v2__1__1.stl"/>
      </geometry>
      <material name="silver"/>
    </visual>
    <collision>
      <origin xyz="0.0 -0.053437 0.045399" rpy="0 0 0"/>
      <geometry>
        <mesh filename="../meshes/Upper_leg_v2__1__1.stl"/>
      </geometry>
    </collision>
  </link>
  <link name="Upper_leg_v2_1">
    <inertial>
      <origin xyz="3.857041070010626e-17 0.019999706649676277 -0.07192876729347247" rpy="0 0 0"/>
      <mass value="0.1431308285816426"/>
      <inertia ixx="0.000346" iyy="0.000326" izz="5.6e-05" ixy="0.0" iyz="0.0" ixz="0.0"/>
    </inertial>
    <visual>
      <origin xyz="-0.0 0.088437 0.045399" rpy="0 0 0"/>
      <geometry>
        <mesh filename="../meshes/Upper_leg_v2_1.stl"/>
      </geometry>
      <material name="silver"/>
    </visual>
    <collision>
      <origin xyz="-0.0 0.088437 0.045399" rpy="0 0 0"/>
      <geometry>
        <mesh filename="../meshes/Upper_leg_v2_1.stl"/>
      </geometry>
    </collision>
  </link>
  <link name="Lower_leg_v2__1__1">
    <inertial>
      <origin xyz="0.003675908133282728 0.01500029514740242 -0.05875757794300279" rpy="0 0 0"/>
      <mass value="0.301868005898131"/>
      <inertia ixx="0.000629" iyy="0.000642" izz="6.2e-05" ixy="0.0" iyz="0.0" ixz="2.2e-05"/>
    </inertial>
    <visual>
      <origin xyz="0.0 -0.058437 0.185399" rpy="0 0 0"/>
      <geometry>
        <mesh filename="../meshes/Lower_leg_v2__1__1.stl"/>
      </geometry>
      <material name="silver"/>
    </visual>
    <collision>
      <origin xyz="0.0 -0.058437 0.185399" rpy="0 0 0"/>
      <geometry>
        <mesh filename="../meshes/Lower_leg_v2__1__1.stl"/>
      </geometry>
    </collision>
  </link>
  <link name="Lower_leg_v2_1">
    <inertial>
      <origin xyz="0.0036759081332828213 0.014999708446754995 -0.05875757794300265" rpy="0 0 0"/>
      <mass value="0.301868005898131"/>
      <inertia ixx="0.000629" iyy="0.000642" izz="6.2e-05" ixy="0.0" iyz="0.0" ixz="2.2e-05"/>
    </inertial>
    <visual>
      <origin xyz="-0.0 0.083437 0.185399" rpy="0 0 0"/>
      <geometry>
        <mesh filename="../meshes/Lower_leg_v2_1.stl"/>
      </geometry>
      <material name="silver"/>
    </visual>
    <collision>
      <origin xyz="-0.0 0.083437 0.185399" rpy="0 0 0"/>
      <geometry>
        <mesh filename="../meshes/Lower_leg_v2_1.stl"/>
      </geometry>
    </collision>
  </link>
  <link name="Ankle_v1__1__1">
    <inertial>
      <origin xyz="0.001958378003147547 0.014999483913460926 5.2723018983069636e-05" rpy="0 0 0"/>
      <mass value="0.013454867594222361"/>
      <inertia ixx="0.0" iyy="5e-06" izz="5e-06" ixy="-0.0" iyz="-0.0" ixz="-0.0"/>
    </inertial>
    <visual>
      <origin xyz="-0.0 0.083437 0.325399" rpy="0 0 0"/>
      <geometry>
        <mesh filename="../meshes/Ankle_v1__1__1.stl"/>
      </geometry>
      <material name="silver"/>
    </visual>
    <collision>
      <origin xyz="-0.0 0.083437 0.325399" rpy="0 0 0"/>
      <geometry>
        <mesh filename="../meshes/Ankle_v1__1__1.stl"/>
      </geometry>
    </collision>
  </link>
  <link name="Ankle_v1__2__1">
    <inertial>
      <origin xyz="0.001958378003147454 0.015000070614108352 5.2723018982958614e-05" rpy="0 0 0"/>
      <mass value="0.013454867594222361"/>
      <inertia ixx="0.0" iyy="5e-06" izz="5e-06" ixy="-0.0" iyz="-0.0" ixz="-0.0"/>
    </inertial>
    <visual>
      <origin xyz="0.0 -0.058437 0.325399" rpy="0 0 0"/>
      <geometry>
        <mesh filename="../meshes/Ankle_v1__2__1.stl"/>
      </geometry>
      <material name="silver"/>
    </visual>
    <collision>
      <origin xyz="0.0 -0.058437 0.325399" rpy="0 0 0"/>
      <geometry>
        <mesh filename="../meshes/Ankle_v1__2__1.stl"/>
      </geometry>
    </collision>
  </link>
  <link name="Foot_v1__1__1">
    <inertial>
      <origin xyz="0.05260285295726386 3.9472407584173475e-07 -0.03676333019729189" rpy="0 0 0"/>
      <mass value="0.18191482193416827"/>
      <inertia ixx="9.7e-05" iyy="0.000254" izz="0.000307" ixy="0.0" iyz="-0.0" ixz="1e-05"/>
    </inertial>
    <visual>
      <origin xyz="0.035 -0.073437 0.325328" rpy="0 0 0"/>
      <geometry>
        <mesh filename="../meshes/Foot_v1__1__1.stl"/>
      </geometry>
      <material name="silver"/>
    </visual>
    <collision>
      <origin xyz="0.035 -0.073437 0.325328" rpy="0 0 0"/>
      <geometry>
        <mesh filename="../meshes/Foot_v1__1__1.stl"/>
      </geometry>
    </collision>
  </link>
  <link name="Foot_v1_1">
    <inertial>
      <origin xyz="0.05260285295726397 -1.919765715702182e-07 -0.036763330197291666" rpy="0 0 0"/>
      <mass value="0.18191482193416827"/>
      <inertia ixx="9.7e-05" iyy="0.000254" izz="0.000307" ixy="0.0" iyz="-0.0" ixz="1e-05"/>
    </inertial>
    <visual>
      <origin xyz="0.035 0.068437 0.325328" rpy="0 0 0"/>
      <geometry>
        <mesh filename="../meshes/Foot_v1_1.stl"/>
      </geometry>
      <material name="silver"/>
    </visual>
    <collision>
      <origin xyz="0.035 0.068437 0.325328" rpy="0 0 0"/>
      <geometry>
        <mesh filename="../meshes/Foot_v1_1.stl"/>
      </geometry>
    </collision>
  </link>
  <joint name="Revolute 1" type="continuous">
    <origin xyz="0.0 0.073437 0.0" rpy="0 0 0"/>
    <parent link="base_link"/>
    <child link="Hip_v1__1__1"/>
    <axis xyz="-0.0 -0.0 1.0"/>
  </joint>
  <joint name="Revolute 2" type="continuous">
    <origin xyz="0.0 -0.073437 0.0" rpy="0 0 0"/>
    <parent link="base_link"/>
    <child link="Hip_v1_1"/>
    <axis xyz="0.0 -0.0 -1.0"/>
  </joint>
  <joint name="Revolute 3" type="continuous">
    <origin xyz="-0.035 0.0 -0.045328" rpy="0 0 0"/>
    <parent link="Hip_v1__1__1"/>
    <child link="Hip_joint_v1_1"/>
    <axis xyz="1.0 0.0 0.0"/>
  </joint>
  <joint name="Revolute 4" type="continuous">
    <origin xyz="-0.035 0.0 -0.045328" rpy="0 0 0"/>
    <parent link="Hip_v1_1"/>
    <child link="Ankle_v1_1"/>
    <axis xyz="1.0 0.0 0.0"/>
  </joint>
  <joint name="Revolute 5" type="continuous">
    <origin xyz="0.035 -0.02 -7.1e-05" rpy="0 0 0"/>
    <parent link="Hip_joint_v1_1"/>
    <child link="Upper_leg_v2__1__1"/>
    <axis xyz="-0.0 -1.0 0.0"/>
  </joint>
  <joint name="Revolute 6" type="continuous">
    <origin xyz="0.035 -0.015 -7.1e-05" rpy="0 0 0"/>
    <parent link="Ankle_v1_1"/>
    <child link="Upper_leg_v2_1"/>
    <axis xyz="0.0 -1.0 0.0"/>
  </joint>
  <joint name="Revolute 7" type="continuous">
    <origin xyz="0.0 0.005 -0.14" rpy="0 0 0"/>
    <parent link="Upper_leg_v2__1__1"/>
    <child link="Lower_leg_v2__1__1"/>
    <axis xyz="0.0 1.0 0.0"/>
  </joint>
  <joint name="Revolute 8" type="continuous">
    <origin xyz="0.0 0.005 -0.14" rpy="0 0 0"/>
    <parent link="Upper_leg_v2_1"/>
    <child link="Lower_leg_v2_1"/>
    <axis xyz="0.0 1.0 0.0"/>
  </joint>
  <joint name="Revolute 9" type="continuous">
    <origin xyz="0.0 0.0 -0.14" rpy="0 0 0"/>
    <parent link="Lower_leg_v2_1"/>
    <child link="Ankle_v1__1__1"/>
    <axis xyz="0.0 -1.0 0.0"/>
  </joint>
  <joint name="Revolute 10" type="continuous">
    <origin xyz="0.0 0.0 -0.14" rpy="0 0 0"/>
    <parent link="Lower_leg_v2__1__1"/>
    <child link="Ankle_v1__2__1"/>
    <axis xyz="-0.0 -1.0 0.0"/>
  </joint>
  <joint name="Revolute 11" type="continuous">
    <origin xyz="-0.035 0.015 7.1e-05" rpy="0 0 0"/>
    <parent link="Ankle_v1__2__1"/>
    <child link="Foot_v1__1__1"/>
    <axis xyz="-1.0 0.0 -0.0"/>
  </joint>
  <joint name="Revolute 12" type="continuous">
    <origin xyz="-0.035 0.015 7.1e-05" rpy="0 0 0"/>
    <parent link="Ankle_v1__1__1"/>
    <child link="Foot_v1_1"/>
    <axis xyz="-1.0 0.0 -0.0"/>
  </joint>
</robot>
